<?xml version="1.0"?>
<robot name="micro_bot">

  <!-- ================= BASE ================= -->
  <link name="base_link">
    <inertial>
      <mass value="5.0"/>
      <inertia ixx="0.2" iyy="0.2" izz="0.2"
               ixy="0" ixz="0" iyz="0"/>
    </inertial>

    <visual>
      <origin xyz="0 0 0.05"/>
      <geometry>
        <box size="0.4 0.3 0.1"/>
      </geometry>
    </visual>

    <collision>
      <origin xyz="0 0 0.05"/>
      <geometry>
        <box size="0.4 0.3 0.1"/>
      </geometry>
    </collision>
  </link>

  <!-- ================= LEFT WHEEL ================= -->
  <link name="left_wheel">
    <inertial>
      <mass value="0.5"/>
      <inertia ixx="0.001" iyy="0.001" izz="0.001"
               ixy="0" ixz="0" iyz="0"/>
    </inertial>

    <visual>
      <origin rpy="0 1.5708 0"/>
      <geometry>
        <cylinder radius="0.05" length="0.02"/>
      </geometry>
    </visual>

    <collision>
      <origin rpy="0 1.5708 0"/>
      <geometry>
        <cylinder radius="0.05" length="0.02"/>
      </geometry>
    </collision>
  </link>

  <joint name="left_wheel_joint" type="continuous">
    <parent link="base_link"/>
    <child link="left_wheel"/>
    <origin xyz="0 0.15 0.05"/>
    <axis xyz="0 1 0"/>
  </joint>

  <!-- ================= RIGHT WHEEL ================= -->
  <link name="right_wheel">
    <inertial>
      <mass value="0.5"/>
      <inertia ixx="0.001" iyy="0.001" izz="0.001"
               ixy="0" ixz="0" iyz="0"/>
    </inertial>

    <visual>
      <origin rpy="0 1.5708 0"/>
      <geometry>
        <cylinder radius="0.05" length="0.02"/>
      </geometry>
    </visual>

    <collision>
      <origin rpy="0 1.5708 0"/>
      <geometry>
        <cylinder radius="0.05" length="0.02"/>
      </geometry>
    </collision>
  </link>

  <joint name="right_wheel_joint" type="continuous">
    <parent link="base_link"/>
    <child link="right_wheel"/>
    <origin xyz="0 -0.15 0.05"/>
    <axis xyz="0 1 0"/>
  </joint>

  <!-- ================= CAMERA ================= -->
  <link name="camera_link">
    <visual>
      <geometry>
        <box size="0.05 0.05 0.05"/>
      </geometry>
    </visual>
  </link>

  <joint name="camera_joint" type="fixed">
    <parent link="base_link"/>
    <child link="camera_link"/>
    <origin xyz="0.15 0 0.15" rpy="0 0 0"/>
  </joint>

  <!-- ================= GAZEBO PLUGINS ================= -->

  <!-- Diff Drive -->
  <gazebo>
    <plugin
      filename="gz-sim-diff-drive-system"
      name="gz::sim::systems::DiffDrive">

      <left_joint>left_wheel_joint</left_joint>
      <right_joint>right_wheel_joint</right_joint>

      <wheel_separation>0.30</wheel_separation>
      <wheel_radius>0.05</wheel_radius>

      <odom_frame>odom</odom_frame>
      <robot_base_frame>base_link</robot_base_frame>

      <cmd_vel_topic>cmd_vel</cmd_vel_topic>
      <odom_topic>odom</odom_topic>

    </plugin>
  </gazebo>

  <!-- Camera sensor -->
  <gazebo reference="camera_link">
    <sensor name="camera_sensor" type="camera">
      <update_rate>30</update_rate>

      <camera>
        <horizontal_fov>1.3962634</horizontal_fov>
        <image>
          <width>640</width>
          <height>480</height>
          <format>R8G8B8</format>
        </image>
        <clip>
          <near>0.1</near>
          <far>50.0</far>
        </clip>
      </camera>

      <plugin
        filename="libgz-sim-camera-system.so"
        name="gz::sim::systems::Camera">
        <ros>
          <namespace>/camera</namespace>
        </ros>
        <frame_name>camera_optical_frame</frame_name>
      </plugin>
    </sensor>
  </gazebo>
    <!-- ================= LiDAR ================= -->

  <!-- LiDAR link -->
  <link name="lidar_link">
    <visual>
      <geometry>
        <cylinder radius="0.03" length="0.05"/>
      </geometry>
    </visual>
  </link>

  <!-- LiDAR joint -->
  <joint name="lidar_joint" type="fixed">
    <parent link="base_link"/>
    <child link="lidar_link"/>
    <origin xyz="0.2 0 0.18" rpy="0 0 0"/>
  </joint>

  <!-- Gazebo Harmonic LiDAR sensor -->
  <gazebo reference="lidar_link">
    <sensor name="lidar_sensor" type="gpu_lidar">
      <update_rate>10</update_rate>

      <ray>
        <scan>
          <horizontal>
            <samples>720</samples>
            <min_angle>-3.14159</min_angle>
            <max_angle>3.14159</max_angle>
          </horizontal>
        </scan>
        <range>
          <min>0.1</min>
          <max>10.0</max>
        </range>
      </ray>

      <plugin
        filename="libgz-sim8-gpu-lidar-system.so"
        name="gz::sim::systems::GpuLidar">
        <ros>
          <namespace>/</namespace>
          <remapping>~/out:=scan</remapping>
        </ros>
        <frame_name>lidar_link</frame_name>
      </plugin>
    </sensor>
  </gazebo>

</robot>
